Workbook

Sheet START HERE
A1: BROTHERHOOD YOUTH SPORTS FEST - CONTROL WORKBOOK | B1: BROTHERHOOD YOUTH SPORTS FEST - CONTROL WORKBOOK | C1: BROTHERHOOD YOUTH SPORTS FEST - CONTROL WORKBOOK | D1: BROTHERHOOD YOUTH SPORTS FEST - CONTROL WORKBOOK | E1: BROTHERHOOD YOUTH SPORTS FEST - CONTROL WORKBOOK | F1: BROTHERHOOD YOUTH SPORTS FEST - CONTROL WORKBOOK | G1: BROTHERHOOD YOUTH SPORTS FEST - CONTROL WORKBOOK | H1: BROTHERHOOD YOUTH SPORTS FEST - CONTROL WORKBOOK
A2: BROTHERHOOD YOUTH SPORTS FEST - CONTROL WORKBOOK | B2: BROTHERHOOD YOUTH SPORTS FEST - CONTROL WORKBOOK | C2: BROTHERHOOD YOUTH SPORTS FEST - CONTROL WORKBOOK | D2: BROTHERHOOD YOUTH SPORTS FEST - CONTROL WORKBOOK | E2: BROTHERHOOD YOUTH SPORTS FEST - CONTROL WORKBOOK | F2: BROTHERHOOD YOUTH SPORTS FEST - CONTROL WORKBOOK | G2: BROTHERHOOD YOUTH SPORTS FEST - CONTROL WORKBOOK | H2: BROTHERHOOD YOUTH SPORTS FEST - CONTROL WORKBOOK
A4: Purpose: Track player eligibility, detect league-rule breaches, record winners and calculate team points.
A6: STEP | B6: WHAT TO DO
A7: 1 | B7: Enter every player's name in Team Rosters. Use the assigned Player Code when recording appearances.
A8: 2 | B8: Enter league winners. The Qualifiers sheet ranks each sport/category by group; semifinal teams fill automatically and final teams follow semifinal winners.
A9: 3 | B9: Select the winner for each completed match. Both sides receive 0 until a valid winner is entered.
A10: 4 | B10: In Player Usage, enter all 4 Player Codes for each doubles match: two players from each team.
A11: 5 | B11: Check Rule Status. A player's third league match against the same opposing team is flagged VIOLATION.
A12: 6 | B12: Use Dashboard for team points, breach counts and potential -20 penalties.
A14: IMPORTANT RULE INTERPRETATION
A15: Rule applied | B15: One player may play against the same opposing team in no more than 2 league matches, counted across all sports.
A16: Audit detail | B16: Sport and category remain visible for each appearance so the exact matches can be checked.
A17: Win points | B17: 10 points are awarded to the winning team for every completed match.
A18: Penalty view | B18: Dashboard shows a potential deduction of 20 points per flagged violating appearance, in line with the supplied rules.

Sheet Dashboard
A1: TOURNAMENT DASHBOARD | B1: TOURNAMENT DASHBOARD | C1: TOURNAMENT DASHBOARD | D1: TOURNAMENT DASHBOARD | E1: TOURNAMENT DASHBOARD | F1: TOURNAMENT DASHBOARD | G1: TOURNAMENT DASHBOARD | H1: TOURNAMENT DASHBOARD | I1: TOURNAMENT DASHBOARD | J1: TOURNAMENT DASHBOARD
A2: TOURNAMENT DASHBOARD | B2: TOURNAMENT DASHBOARD | C2: TOURNAMENT DASHBOARD | D2: TOURNAMENT DASHBOARD | E2: TOURNAMENT DASHBOARD | F2: TOURNAMENT DASHBOARD | G2: TOURNAMENT DASHBOARD | H2: TOURNAMENT DASHBOARD | I2: TOURNAMENT DASHBOARD | J2: TOURNAMENT DASHBOARD
A4: LIVE CONTROL SUMMARY
A5: Metric | B5: Value
A6: Matches completed | B6: =COUNTIF('Match Results'!$N$6:$N$185,"YES") -> 170
A7: Total matches | B7: 180
A8: Player entries recorded | B8: =COUNTA('Player Usage'!$J$6:$J$875) -> 0
A9: Rule violations | B9: =COUNTIF('Player Usage'!$N$6:$N$875,"VIOLATION") -> 0
A11: TEAM STANDINGS
A12: Team | B12: League Wins | C12: Knockout Wins | D12: Total Wins | E12: Gross Points | F12: Rule Breaches | G12: Potential Penalty | H12: Net Points | I12: Matches Played | J12: Status
A13: A1 | B13: =COUNTIFS('Match Results'!$I$6:$I$185,A13,'Match Results'!$E$6:$E$185,"League",'Match Results'!$J$6:$J$185,"VALID") -> 3 | C13: =COUNTIFS('Match Results'!$I$6:$I$185,A13,'Match Results'!$E$6:$E$185,"<>League",'Match Results'!$J$6:$J$185,"VALID") -> 2 | D13: =B13+C13 -> 5 | E13: =D13*10 -> 50 | F13: =COUNTIFS('Player Usage'!$F$6:$F$875,A13,'Player Usage'!$N$6:$N$875,"VIOLATION") -> 0 | G13: =-F13*10 -> 0 | H13: =E13+G13 -> 50 | I13: =COUNTIFS('Match Results'!$G$6:$G$185,A13,'Match Results'!$N$6:$N$185,"YES")+COUNTIFS('Match Results'!$H$6:$H$185,A13,'Match Results'!$N$6:$N$185,"YES") -> 38 | J13: =IF(F13=0,"COMPLIANT","REVIEW BREACH") -> COMPLIANT
A14: A2 | B14: =COUNTIFS('Match Results'!$I$6:$I$185,A14,'Match Results'!$E$6:$E$185,"League",'Match Results'!$J$6:$J$185,"VALID") -> 11 | C14: =COUNTIFS('Match Results'!$I$6:$I$185,A14,'Match Results'!$E$6:$E$185,"<>League",'Match Results'!$J$6:$J$185,"VALID") -> 0 | D14: =B14+C14 -> 11 | E14: =D14*10 -> 110 | F14: =COUNTIFS('Player Usage'!$F$6:$F$875,A14,'Player Usage'!$N$6:$N$875,"VIOLATION") -> 0 | G14: =-F14*10 -> 0 | H14: =E14+G14 -> 110 | I14: =COUNTIFS('Match Results'!$G$6:$G$185,A14,'Match Results'!$N$6:$N$185,"YES")+COUNTIFS('Match Results'!$H$6:$H$185,A14,'Match Results'!$N$6:$N$185,"YES") -> 36 | J14: =IF(F14=0,"COMPLIANT","REVIEW BREACH") -> COMPLIANT
A15: A3 | B15: =COUNTIFS('Match Results'!$I$6:$I$185,A15,'Match Results'!$E$6:$E$185,"League",'Match Results'!$J$6:$J$185,"VALID") -> 23 | C15: =COUNTIFS('Match Results'!$I$6:$I$185,A15,'Match Results'!$E$6:$E$185,"<>League",'Match Results'!$J$6:$J$185,"VALID") -> 0 | D15: =B15+C15 -> 23 | E15: =D15*10 -> 230 | F15: =COUNTIFS('Player Usage'!$F$6:$F$875,A15,'Player Usage'!$N$6:$N$875,"VIOLATION") -> 0 | G15: =-F15*10 -> 0 | H15: =E15+G15 -> 230 | I15: =COUNTIFS('Match Results'!$G$6:$G$185,A15,'Match Results'!$N$6:$N$185,"YES")+COUNTIFS('Match Results'!$H$6:$H$185,A15,'Match Results'!$N$6:$N$185,"YES") -> 47 | J15: =IF(F15=0,"COMPLIANT","REVIEW BREACH") -> COMPLIANT
A16: A4 | B16: =COUNTIFS('Match Results'!$I$6:$I$185,A16,'Match Results'!$E$6:$E$185,"League",'Match Results'!$J$6:$J$185,"VALID") -> 35 | C16: =COUNTIFS('Match Results'!$I$6:$I$185,A16,'Match Results'!$E$6:$E$185,"<>League",'Match Results'!$J$6:$J$185,"VALID") -> 0 | D16: =B16+C16 -> 35 | E16: =D16*10 -> 350 | F16: =COUNTIFS('Player Usage'!$F$6:$F$875,A16,'Player Usage'!$N$6:$N$875,"VIOLATION") -> 0 | G16: =-F16*10 -> 0 | H16: =E16+G16 -> 350 | I16: =COUNTIFS('Match Results'!$G$6:$G$185,A16,'Match Results'!$N$6:$N$185,"YES")+COUNTIFS('Match Results'!$H$6:$H$185,A16,'Match Results'!$N$6:$N$185,"YES") -> 48 | J16: =IF(F16=0,"COMPLIANT","REVIEW BREACH") -> COMPLIANT
A17: B1 | B17: =COUNTIFS('Match Results'!$I$6:$I$185,A17,'Match Results'!$E$6:$E$185,"League",'Match Results'!$J$6:$J$185,"VALID") -> 0 | C17: =COUNTIFS('Match Results'!$I$6:$I$185,A17,'Match Results'!$E$6:$E$185,"<>League",'Match Results'!$J$6:$J$185,"VALID") -> 0 | D17: =B17+C17 -> 0 | E17: =D17*10 -> 0 | F17: =COUNTIFS('Player Usage'!$F$6:$F$875,A17,'Player Usage'!$N$6:$N$875,"VIOLATION") -> 0 | G17: =-F17*10 -> 0 | H17: =E17+G17 -> 0 | I17: =COUNTIFS('Match Results'!$G$6:$G$185,A17,'Match Results'!$N$6:$N$185,"YES")+COUNTIFS('Match Results'!$H$6:$H$185,A17,'Match Results'!$N$6:$N$185,"YES") -> 36 | J17: =IF(F17=0,"COMPLIANT","REVIEW BREACH") -> COMPLIANT
A18: B2 | B18: =COUNTIFS('Match Results'!$I$6:$I$185,A18,'Match Results'!$E$6:$E$185,"League",'Match Results'!$J$6:$J$185,"VALID") -> 12 | C18: =COUNTIFS('Match Results'!$I$6:$I$185,A18,'Match Results'!$E$6:$E$185,"<>League",'Match Results'!$J$6:$J$185,"VALID") -> 0 | D18: =B18+C18 -> 12 | E18: =D18*10 -> 120 | F18: =COUNTIFS('Player Usage'!$F$6:$F$875,A18,'Player Usage'!$N$6:$N$875,"VIOLATION") -> 0 | G18: =-F18*10 -> 0 | H18: =E18+G18 -> 120 | I18: =COUNTIFS('Match Results'!$G$6:$G$185,A18,'Match Results'!$N$6:$N$185,"YES")+COUNTIFS('Match Results'!$H$6:$H$185,A18,'Match Results'!$N$6:$N$185,"YES") -> 36 | J18: =IF(F18=0,"COMPLIANT","REVIEW BREACH") -> COMPLIANT
A19: B3 | B19: =COUNTIFS('Match Results'!$I$6:$I$185,A19,'Match Results'!$E$6:$E$185,"League",'Match Results'!$J$6:$J$185,"VALID") -> 24 | C19: =COUNTIFS('Match Results'!$I$6:$I$185,A19,'Match Results'!$E$6:$E$185,"<>League",'Match Results'!$J$6:$J$185,"VALID") -> 11 | D19: =B19+C19 -> 35 | E19: =D19*10 -> 350 | F19: =COUNTIFS('Player Usage'!$F$6:$F$875,A19,'Player Usage'!$N$6:$N$875,"VIOLATION") -> 0 | G19: =-F19*10 -> 0 | H19: =E19+G19 -> 350 | I19: =COUNTIFS('Match Results'!$G$6:$G$185,A19,'Match Results'!$N$6:$N$185,"YES")+COUNTIFS('Match Results'!$H$6:$H$185,A19,'Match Results'!$N$6:$N$185,"YES") -> 49 | J19: =IF(F19=0,"COMPLIANT","REVIEW BREACH") -> COMPLIANT
A20: B4 | B20: =COUNTIFS('Match Results'!$I$6:$I$185,A20,'Match Results'!$E$6:$E$185,"League",'Match Results'!$J$6:$J$185,"VALID") -> 36 | C20: =COUNTIFS('Match Results'!$I$6:$I$185,A20,'Match Results'!$E$6:$E$185,"<>League",'Match Results'!$J$6:$J$185,"VALID") -> 13 | D20: =B20+C20 -> 49 | E20: =D20*10 -> 490 | F20: =COUNTIFS('Player Usage'!$F$6:$F$875,A20,'Player Usage'!$N$6:$N$875,"VIOLATION") -> 0 | G20: =-F20*10 -> 0 | H20: =E20+G20 -> 490 | I20: =COUNTIFS('Match Results'!$G$6:$G$185,A20,'Match Results'!$N$6:$N$185,"YES")+COUNTIFS('Match Results'!$H$6:$H$185,A20,'Match Results'!$N$6:$N$185,"YES") -> 50 | J20: =IF(F20=0,"COMPLIANT","REVIEW BREACH") -> COMPLIANT
A22: CONTROL CHECKS
A23: Check | B23: Count | C23: Expected | D23: Status
A24: Invalid winners | B24: =COUNTIF('Match Results'!$J$6:$J$185,"CHECK WINNER") -> 0 | C24: 0 | D24: =IF(B24=C24,"OK","ACTION NEEDED") -> OK
A25: Roster mismatches | B25: =COUNTIF('Player Usage'!$L$6:$L$875,"CHECK ROSTER") -> 0 | C25: 0 | D25: =IF(B25=C25,"OK","ACTION NEEDED") -> OK
A26: League rule violations | B26: =COUNTIF('Player Usage'!$N$6:$N$875,"VIOLATION") -> 0 | C26: 0 | D26: =IF(B26=C26,"OK","ACTION NEEDED") -> OK
A27: Unresolved knockout teams | B27: =COUNTBLANK('Match Results'!$G$150:$G$185)+COUNTBLANK('Match Results'!$H$150:$H$185) -> 0 | C27: 0 | D27: =IF(B27=C27,"OK","ACTION NEEDED") -> OK

Sheet Team Rosters
A1: TEAM ROSTERS | B1: TEAM ROSTERS | C1: TEAM ROSTERS | D1: TEAM ROSTERS | E1: TEAM ROSTERS
A2: TEAM ROSTERS | B2: TEAM ROSTERS | C2: TEAM ROSTERS | D2: TEAM ROSTERS | E2: TEAM ROSTERS
A3: Fill Player Name and Gender. Player Codes are already assigned and must not be changed.
A5: Team | B5: Player Code | C5: Player Name (INPUT) | D5: Gender (INPUT) | E5: Notes
A6: A1 | B6: A1-P01 | C6: SHREYANK JAIN | D6: Male | E6: Captain
A7: A1 | B7: A1-P02 | C7: VANSH RAJESH GARG | D7: Male
A8: A1 | B8: A1-P03 | C8: DEVANSH M AGARWAL | D8: Male
A9: A1 | B9: A1-P04 | C9: AKSHIT GUPTA | D9: Male
A10: A1 | B10: A1-P05 | C10: KETAN AGARWAL | D10: Male
A11: A1 | B11: A1-P06 | C11: MEDHANSH AGARWAL | D11: Male
A12: A1 | B12: A1-P07 | C12: ABHAY GARG | D12: Male
A13: A1 | B13: A1-P08 | C13: ISHAAN GARG | D13: Male
A14: A1 | B14: A1-P09 | C14: ARMAAN AGARWAL | D14: Male
A15: A1 | B15: A1-P10 | C15: ABHIJEET GOYAL | D15: Male
A16: A1 | B16: A1-P11 | C16: YOGESH AGARWAL | D16: Male
A17: A1 | B17: A1-P12 | C17: AKSHAY AGARWAL | D17: Male
A18: A1 | B18: A1-P13 | C18: SHUBHAM AGARWAL | D18: Male
... A20: A1 | B20: A1-P15 | C20: MURARI AGARWAL | D20: Male
A21: A1 | B21: A1-P16 | C21: BHAGYASHREE AGARWAL | D21: Female | E21: Vice Captain
A22: A1 | B22: A1-P17 | C22: PRIYANKA MAHIPAL | D22: Female
A23: A1 | B23: A1-P18 | C23: RASHI AGARWAL | D23: Female
A24: A1 | B24: A1-P19 | C24: RITU GOYAL | D24: Female
A25: A1 | B25: A1-P20 | C25: SIDDHI AGARWAL | D25: Female
A26: A1 | B26: A1-P21 | C26: ASHITA ANKUSH AGARWAL | D26: Female
A27: A1 | B27: A1-P22 | C27: DIVYA MITTAL | D27: Female
A28: A1 | B28: A1-P23 | C28: ISHA GOYAL | D28: Female
A29: A1 | B29: A1-P24 | C29: DEVESH AGARWAL | D29: Male
A30: A1 | B30: A1-P25
A31: A2 | B31: A2-P01 | C31: TARUSH AGARWAL | D31: Male | E31: Captain
A32: A2 | B32: A2-P02 | C32: RAJAT GOYAL | D32: Male
A33: A2 | B33: A2-P03 | C33: RAHUL M AGARWAL | D33: Male
A34: A2 | B34: A2-P04 | C34: KUNJ BANSAL | D34: Male
A35: A2 | B35: A2-P05 | C35: BHAVESH RAKESH AGARWAL | D35: Male
A36: A2 | B36: A2-P06 | C36: DIVIJ GOYAL | D36: Male
A37: A2 | B37: A2-P07 | C37: PRATIK PRAKASH AGARWAL | D37: Male
A38: A2 | B38: A2-P08 | C38: VIRAJ VIJAYKUMAR GARG | D38: Male
A39: A2 | B39: A2-P09 | C39: YASH GOYAL | D39: Male
A40: A2 | B40: A2-P10 | C40: PRANAV AGARWAL | D40: Male
A41: A2 | B41: A2-P11 | C41: SAHIL SANJAY MITTAL | D41: Male
A42: A2 | B42: A2-P12 | C42: ROHAN SUNIL GOYAL | D42: Male
...

Sheet Match Results
A1: MATCH RESULTS & POINTS ENTRY | B1: MATCH RESULTS & POINTS ENTRY | C1: MATCH RESULTS & POINTS ENTRY | D1: MATCH RESULTS & POINTS ENTRY | E1: MATCH RESULTS & POINTS ENTRY | F1: MATCH RESULTS & POINTS ENTRY | G1: MATCH RESULTS & POINTS ENTRY | H1: MATCH RESULTS & POINTS ENTRY | I1: MATCH RESULTS & POINTS ENTRY | J1: MATCH RESULTS & POINTS ENTRY | K1: MATCH RESULTS & POINTS ENTRY | L1: MATCH RESULTS & POINTS ENTRY | M1: MATCH RESULTS & POINTS ENTRY | N1: MATCH RESULTS & POINTS ENTRY | O1: MATCH RESULTS & POINTS ENTRY
A2: MATCH RESULTS & POINTS ENTRY | B2: MATCH RESULTS & POINTS ENTRY | C2: MATCH RESULTS & POINTS ENTRY | D2: MATCH RESULTS & POINTS ENTRY | E2: MATCH RESULTS & POINTS ENTRY | F2: MATCH RESULTS & POINTS ENTRY | G2: MATCH RESULTS & POINTS ENTRY | H2: MATCH RESULTS & POINTS ENTRY | I2: MATCH RESULTS & POINTS ENTRY | J2: MATCH RESULTS & POINTS ENTRY | K2: MATCH RESULTS & POINTS ENTRY | L2: MATCH RESULTS & POINTS ENTRY | M2: MATCH RESULTS & POINTS ENTRY | N2: MATCH RESULTS & POINTS ENTRY | O2: MATCH RESULTS & POINTS ENTRY
A3: Yellow cells are organizer inputs. Semifinal teams populate from Qualifiers; final teams populate after valid semifinal winners are entered.
A5: Match No. | B5: Time | C5: Sport | D5: Category | E5: Stage | F5: Planned Fixture | G5: Team 1 | H5: Team 2 | I5: Winner (INPUT) | J5: Result Check | K5: Team 1 Pts | L5: Team 2 Pts | M5: Loser | N5: Completed? | O5: Notes
A6: 1 | B6: 9:00 AM-9:30 AM | C6: Badminton | D6: Boys Doubles | E6: League | F6: A1 vs A2 | G6: A1 | H6: A2 | I6: A2 | J6: =IF(I6="","PENDING",IF(OR(I6=G6,I6=H6),"VALID","CHECK WINNER")) -> VALID | M6: =IF(J6="VALID",IF(I6=G6,H6,G6),"") -> A1 | N6: =IF(J6="VALID","YES","NO") -> YES
A7: 2 | B7: 9:00 AM-9:30 AM | C7: Badminton | D7: Girls Doubles | E7: League | F7: A3 vs A4 | G7: A3 | H7: A4 | I7: A4 | J7: =IF(I7="","PENDING",IF(OR(I7=G7,I7=H7),"VALID","CHECK WINNER")) -> VALID | M7: =IF(J7="VALID",IF(I7=G7,H7,G7),"") -> A3 | N7: =IF(J7="VALID","YES","NO") -> YES
A8: 3 | B8: 9:00 AM-9:30 AM | C8: Badminton | D8: Mixed Doubles | E8: League | F8: B1 vs B4 | G8: B1 | H8: B4 | I8: B4 | J8: =IF(I8="","PENDING",IF(OR(I8=G8,I8=H8),"VALID","CHECK WINNER")) -> VALID | M8: =IF(J8="VALID",IF(I8=G8,H8,G8),"") -> B1 | N8: =IF(J8="VALID","YES","NO") -> YES
A9: 4 | B9: 9:00 AM-9:30 AM | C9: Pickleball | D9: Girls Doubles | E9: League | F9: A1 vs A4 | G9: A1 | H9: A4 | I9: A4 | J9: =IF(I9="","PENDING",IF(OR(I9=G9,I9=H9),"VALID","CHECK WINNER")) -> VALID | M9: =IF(J9="VALID",IF(I9=G9,H9,G9),"") -> A1 | N9: =IF(J9="VALID","YES","NO") -> YES
A10: 5 | B10: 9:00 AM-9:30 AM | C10: Pickleball | D10: Mixed Doubles | E10: League | F10: A2 vs A3 | G10: A2 | H10: A3 | I10: A3 | J10: =IF(I10="","PENDING",IF(OR(I10=G10,I10=H10),"VALID","CHECK WINNER")) -> VALID | M10: =IF(J10="VALID",IF(I10=G10,H10,G10),"") -> A2 | N10: =IF(J10="VALID","YES","NO") -> YES
A11: 6 | B11: 9:00 AM-9:30 AM | C11: Pickleball | D11: Boys Doubles | E11: League | F11: B2 vs B3 | G11: B2 | H11: B3 | I11: B3 | J11: =IF(I11="","PENDING",IF(OR(I11=G11,I11=H11),"VALID","CHECK WINNER")) -> VALID | M11: =IF(J11="VALID",IF(I11=G11,H11,G11),"") -> B2 | N11: =IF(J11="VALID","YES","NO") -> YES
A12: 7 | B12: 9:00 AM-9:30 AM | C12: Table Tennis | D12: Boys Doubles | E12: League | F12: B1 vs B2 | G12: B1 | H12: B2 | I12: B2 | J12: =IF(I12="","PENDING",IF(OR(I12=G12,I12=H12),"VALID","CHECK WINNER")) -> VALID | M12: =IF(J12="VALID",IF(I12=G12,H12,G12),"") -> B1 | N12: =IF(J12="VALID","YES","NO") -> YES
A13: 8 | B13: 9:00 AM-9:30 AM | C13: Table Tennis | D13: Mixed Doubles | E13: League | F13: B3 vs B4 | G13: B3 | H13: B4 | I13: B4 | J13: =IF(I13="","PENDING",IF(OR(I13=G13,I13=H13),"VALID","CHECK WINNER")) -> VALID | M13: =IF(J13="VALID",IF(I13=G13,H13,G13),"") -> B3 | N13: =IF(J13="VALID","YES","NO") -> YES
A14: 9 | B14: 9:00 AM-9:30 AM | C14: Carrom | D14: Girls Doubles | E14: League | F14: A1 vs A3 | G14: A1 | H14: A3 | I14: A3 | J14: =IF(I14="","PENDING",IF(OR(I14=G14,I14=H14),"VALID","CHECK WINNER")) -> VALID | M14: =IF(J14="VALID",IF(I14=G14,H14,G14),"") -> A1 | N14: =IF(J14="VALID","YES","NO") -> YES
A15: 10 | B15: 9:00 AM-9:30 AM | C15: Carrom | D15: Boys Doubles | E15: League | F15: A2 vs A4 | G15: A2 | H15: A4 | I15: A4 | J15: =IF(I15="","PENDING",IF(OR(I15=G15,I15=H15),"VALID","CHECK WINNER")) -> VALID | M15: =IF(J15="VALID",IF(I15=G15,H15,G15),"") -> A2 | N15: =IF(J15="VALID","YES","NO") -> YES
A16: 11 | B16: 9:00 AM-9:30 AM | C16: Carrom | D16: Mixed Doubles | E16: League | F16: B2 vs B4 | G16: B2 | H16: B4 | I16: B4 | J16: =IF(I16="","PENDING",IF(OR(I16=G16,I16=H16),"VALID","CHECK WINNER")) -> VALID | M16: =IF(J16="VALID",IF(I16=G16,H16,G16),"") -> B2 | N16: =IF(J16="VALID","YES","NO") -> YES
A17: 12 | B17: 9:00 AM-9:30 AM | C17: Football | D17: Boys | E17: League | F17: B1 vs B3 | G17: B1 | H17: B3 | I17: B3 | J17: =IF(I17="","PENDING",IF(OR(I17=G17,I17=H17),"VALID","CHECK WINNER")) -> VALID | M17: =IF(J17="VALID",IF(I17=G17,H17,G17),"") -> B1 | N17: =IF(J17="VALID","YES","NO") -> YES
... A149: 144 | B149: 2:30 PM-3:00 PM | C149: Football | D149: Boys | E149: League | F149: A1 vs A2 | G149: A1 | H149: A2 | I149: A2 | J149: =IF(I149="","PENDING",IF(OR(I149=G149,I149=H149),"VALID","CHECK WINNER")) -> VALID | M149: =IF(J149="VALID",IF(I149=G149,H149,G149),"") -> A1 | N149: =IF(J149="VALID","YES","NO") -> YES
A150: 145 | B150: 3:30 PM-4:00 PM | C150: Carrom | D150: Boys Doubles | E150: SF1 | F150: Group A #1 vs Group B #2 | G150: =Qualifiers!$C$6 -> A1 | H150: =Qualifiers!$F$6 -> B3 | I150: A1 | J150: =IF(I150="","PENDING",IF(OR(I150=G150,I150=H150),"VALID","CHECK WINNER")) -> VALID | K150: 30 | L150: 0 | M150: =IF(J150="VALID",IF(I150=G150,H150,G150),"") -> B3 | N150: =IF(J150="VALID","YES","NO") -> YES | O150: Source: SEMIS AND FINAL.pdf
A151: 146 | B151: 3:30 PM-4:00 PM | C151: Carrom | D151: Girls Doubles | E151: SF1 | F151: Group A #1 vs Group B #2 | G151: =Qualifiers!$C$7 -> A4 | H151: =Qualifiers!$F$7 -> B3 | I151: =Qualifiers!$F$7 -> B3 | J151: =IF(I151="","PENDING",IF(OR(I151=G151,I151=H151),"VALID","CHECK WINNER")) -> VALID | M151: =IF(J151="VALID",IF(I151=G151,H151,G151),"") -> A4 | N151: =IF(J151="VALID","YES","NO") -> YES | O151: Source: SEMIS AND FINAL.pdf
A152: 147 | B152: 3:30 PM-4:00 PM | C152: Carrom | D152: Mixed Doubles | E152: SF1 | F152: Group A #1 vs Group B #2 | G152: =Qualifiers!$C$8 -> A4 | H152: =Qualifiers!$F$8 -> B3 | I152: =Qualifiers!$F$8 -> B3 | J152: =IF(I152="","PENDING",IF(OR(I152=G152,I152=H152),"VALID","CHECK WINNER")) -> VALID | M152: =IF(J152="VALID",IF(I152=G152,H152,G152),"") -> A4 | N152: =IF(J152="VALID","YES","NO") -> YES | O152: Source: SEMIS AND FINAL.pdf
A153: 148 | B153: 3:30 PM-4:00 PM | C153: Table Tennis | D153: Boys Doubles | E153: SF1 | F153: Group A #1 vs Group B #2 | G153: =Qualifiers!$C$9 -> A4 | H153: =Qualifiers!$F$9 -> B3 | I153: =Qualifiers!$F$9 -> B3 | J153: =IF(I153="","PENDING",IF(OR(I153=G153,I153=H153),"VALID","CHECK WINNER")) -> VALID | M153: =IF(J153="VALID",IF(I153=G153,H153,G153),"") -> A4 | N153: =IF(J153="VALID","YES","NO") -> YES | O153: Source: SEMIS AND FINAL.pdf
A154: 149 | B154: 3:30 PM-4:00 PM | C154: Table Tennis | D154: Mixed Doubles | E154: SF1 | F154: Group A #1 vs Group B #2 | G154: =Qualifiers!$C$10 -> A4 | H154: =Qualifiers!$F$10 -> B3 | I154: =Qualifiers!$F$10 -> B3 | J154: =IF(I154="","PENDING",IF(OR(I154=G154,I154=H154),"VALID","CHECK WINNER")) -> VALID | M154: =IF(J154="VALID",IF(I154=G154,H154,G154),"") -> A4 | N154: =IF(J154="VALID","YES","NO") -> YES | O154: Source: SEMIS AND FINAL.pdf
A155: 150 | B155: 4:00 PM-4:30 PM | C155: Carrom | D155: Boys Doubles | E155: SF2 | F155: Group A #2 vs Group B #1 | G155: =Qualifiers!$D$6 -> A4 | H155: =Qualifiers!$E$6 -> B4 | I155: =Qualifiers!$E$6 -> B4 | J155: =IF(I155="","PENDING",IF(OR(I155=G155,I155=H155),"VALID","CHECK WINNER")) -> VALID | M155: =IF(J155="VALID",IF(I155=G155,H155,G155),"") -> A4 | N155: =IF(J155="VALID","YES","NO") -> YES | O155: Source: SEMIS AND FINAL.pdf
A156: 151 | B156: 4:00 PM-4:30 PM | C156: Carrom | D156: Girls Doubles | E156: SF2 | F156: Group A #2 vs Group B #1 | G156: =Qualifiers!$D$7 -> A3 | H156: =Qualifiers!$E$7 -> B4 | I156: =Qualifiers!$E$7 -> B4 | J156: =IF(I156="","PENDING",IF(OR(I156=G156,I156=H156),"VALID","CHECK WINNER")) -> VALID | M156: =IF(J156="VALID",IF(I156=G156,H156,G156),"") -> A3 | N156: =IF(J156="VALID","YES","NO") -> YES | O156: Source: SEMIS AND FINAL.pdf
A157: 152 | B157: 4:00 PM-4:30 PM | C157: Carrom | D157: Mixed Doubles | E157: SF2 | F157: Group A #2 vs Group B #1 | G157: =Qualifiers!$D$8 -> A3 | H157: =Qualifiers!$E$8 -> B4 | I157: =Qualifiers!$E$8 -> B4 | J157: =IF(I157="","PENDING",IF(OR(I157=G157,I157=H157),"VALID","CHECK WINNER")) -> VALID | M157: =IF(J157="VALID",IF(I157=G157,H157,G157),"") -> A3 | N157: =IF(J157="VALID","YES","NO") -> YES | O157: Source: SEMIS AND FINAL.pdf
A158: 153 | B158: 4:00 PM-4:30 PM | C158: Table Tennis | D158: Boys Doubles | E158: SF2 | F158: Group A #2 vs Group B #1 | G158: =Qualifiers!$D$9 -> A3 | H158: =Qualifiers!$E$9 -> B4 | I158: =Qualifiers!$E$9 -> B4 | J158: =IF(I158="","PENDING",IF(OR(I158=G158,I158=H158),"VALID","CHECK WINNER")) -> VALID | M158: =IF(J158="VALID",IF(I158=G158,H158,G158),"") -> A3 | N158: =IF(J158="VALID","YES","NO") -> YES | O158: Source: SEMIS AND FINAL.pdf
A159: 154 | B159: 4:00 PM-4:30 PM | C159: Table Tennis | D159: Mixed Doubles | E159: SF2 | F159: Group A #2 vs Group B #1 | G159: =Qualifiers!$D$10 -> A3 | H159: =Qualifiers!$E$10 -> B4 | I159: =Qualifiers!$E$10 -> B4 | J159: =IF(I159="","PENDING",IF(OR(I159=G159,I159=H159),"VALID","CHECK WINNER")) -> VALID | M159: =IF(J159="VALID",IF(I159=G159,H159,G159),"") -> A3 | N159: =IF(J159="VALID","YES","NO") -> YES | O159: Source: SEMIS AND FINAL.pdf
A160: 155 | B160: 4:30 PM-5:00 PM | C160: Badminton | D160: Boys Doubles | E160: SF1 | F160: Group A #1 vs Group B #2 | G160: =Qualifiers!$C$11 -> A4 | H160: =Qualifiers!$F$11 -> B3 | I160: =Qualifiers!$F$11 -> B3 | J160: =IF(I160="","PENDING",IF(OR(I160=G160,I160=H160),"VALID","CHECK WINNER")) -> VALID | M160: =IF(J160="VALID",IF(I160=G160,H160,G160),"") -> A4 | N160: =IF(J160="VALID","YES","NO") -> YES | O160: Source: SEMIS AND FINAL.pdf
A161: 156 | B161: 4:30 PM-5:00 PM | C161: Badminton | D161: Girls Doubles | E161: SF1 | F161: Group A #1 vs Group B #2 | G161: =Qualifiers!$C$12 -> A4 | H161: =Qualifiers!$F$12 -> B3 | I161: =Qualifiers!$F$12 -> B3 | J161: =IF(I161="","PENDING",IF(OR(I161=G161,I161=H161),"VALID","CHECK WINNER")) -> VALID | M161: =IF(J161="VALID",IF(I161=G161,H161,G161),"") -> A4 | N161: =IF(J161="VALID","YES","NO") -> YES | O161: Source: SEMIS AND FINAL.pdf
A162: 157 | B162: 4:30 PM-5:00 PM | C162: Badminton | D162: Mixed Doubles | E162: SF1 | F162: Group A #1 vs Group B #2 | G162: =Qualifiers!$C$13 -> A4 | H162: =Qualifiers!$F$13 -> B3 | I162: =Qualifiers!$F$13 -> B3 | J162: =IF(I162="","PENDING",IF(OR(I162=G162,I162=H162),"VALID","CHECK WINNER")) -> VALID | M162: =IF(J162="VALID",IF(I162=G162,H162,G162),"") -> A4 | N162: =IF(J162="VALID","YES","NO") -> YES | O162: Source: SEMIS AND FINAL.pdf
A163: 158 | B163: 5:00 PM-5:30 PM | C163: Badminton | D163: Boys Doubles | E163: SF2 | F163: Group A #2 vs Group B #1 | G163: =Qualifiers!$D$11 -> A3 | H163: =Qualifiers!$E$11 -> B4 | I163: =Qualifiers!$E$11 -> B4 | J163: =IF(I163="","PENDING",IF(OR(I163=G163,I163=H163),"VALID","CHECK WINNER")) -> VALID | M163: =IF(J163="VALID",IF(I163=G163,H163,G163),"") -> A3 | N163: =IF(J163="VALID","YES","NO") -> YES | O163: Source: SEMIS AND FINAL.pdf
A164: 159 | B164: 5:00 PM-5:30 PM | C164: Badminton | D164: Girls Doubles | E164: SF2 | F164: Group A #2 vs Group B #1 | G164: =Qualifiers!$D$12 -> A3 | H164: =Qualifiers!$E$12 -> B4 | I164: =Qualifiers!$E$12 -> B4 | J164: =IF(I164="","PENDING",IF(OR(I164=G164,I164=H164),"VALID","CHECK WINNER")) -> VALID | M164: =IF(J164="VALID",IF(I164=G164,H164,G164),"") -> A3 | N164: =IF(J164="VALID","YES","NO") -> YES | O164: Source: SEMIS AND FINAL.pdf
A165: 160 | B165: 5:00 PM-5:30 PM | C165: Badminton | D165: Mixed Doubles | E165: SF2 | F165: Group A #2 vs Group B #1 | G165: =Qualifiers!$D$13 -> A3 | H165: =Qualifiers!$E$13 -> B4 | I165: =Qualifiers!$E$13 -> B4 | J165: =IF(I165="","PENDING",IF(OR(I165=G165,I165=H165),"VALID","CHECK WINNER")) -> VALID | M165: =IF(J165="VALID",IF(I165=G165,H165,G165),"") -> A3 | N165: =IF(J165="VALID","YES","NO") -> YES | O165: Source: SEMIS AND FINAL.pdf
A166: 161 | B166: 5:30 PM-6:00 PM | C166: Pickleball | D166: Boys Doubles | E166: SF1 | F166: Group A #1 vs Group B #2 | G166: =Qualifiers!$C$14 -> A4 | H166: =Qualifiers!$F$14 -> B3 | I166: =Qualifiers!$F$14 -> B3 | J166: =IF(I166="","PENDING",IF(OR(I166=G166,I166=H166),"VALID","CHECK WINNER")) -> VALID | M166: =IF(J166="VALID",IF(I166=G166,H166,G166),"") -> A4 | N166: =IF(J166="VALID","YES","NO") -> YES | O166: Source: SEMIS AND FINAL.pdf
A167: 162 | B167: 5:30 PM-6:00 PM | C167: Pickleball | D167: Girls Doubles | E167: SF1 | F167: Group A #1 vs Group B #2 | G167: =Qualifiers!$C$15 -> A4 | H167: =Qualifiers!$F$15 -> B3 | I167: =Qualifiers!$F$15 -> B3 | J167: =IF(I167="","PENDING",IF(OR(I167=G167,I167=H167),"VALID","CHECK WINNER")) -> VALID | M167: =IF(J167="VALID",IF(I167=G167,H167,G167),"") -> A4 | N167: =IF(J167="VALID","YES","NO") -> YES | O167: Source: SEMIS AND FINAL.pdf
A168: 163 | B168: 5:30 PM-6:00 PM | C168: Pickleball | D168: Mixed Doubles | E168: SF1 | F168: Group A #1 vs Group B #2 | G168: =Qualifiers!$C$16 -> A4 | H168: =Qualifiers!$F$16 -> B3 | I168: =Qualifiers!$F$16 -> B3 | J168: =IF(I168="","PENDING",IF(OR(I168=G168,I168=H168),"VALID","CHECK WINNER")) -> VALID | M168: =IF(J168="VALID",IF(I168=G168,H168,G168),"") -> A4 | N168: =IF(J168="VALID","YES","NO") -> YES | O168: Source: SEMIS AND FINAL.pdf
A169: 164 | B169: 5:30 PM-6:00 PM | C169: Football | D169: Boys | E169: SF2 | F169: Group A #2 vs Group B #1 | G169: =Qualifiers!$D$17 -> A3 | H169: =Qualifiers!$E$17 -> B4 | I169: =Qualifiers!$E$17 -> B4 | J169: =IF(I169="","PENDING",IF(OR(I169=G169,I169=H169),"VALID","CHECK WINNER")) -> VALID | M169: =IF(J169="VALID",IF(I169=G169,H169,G169),"") -> A3 | N169: =IF(J169="VALID","YES","NO") -> YES | O169: Source: SEMIS AND FINAL.pdf
A170: 165 | B170: 6:00 PM-6:30 PM | C170: Pickleball | D170: Boys Doubles | E170: SF2 | F170: Group A #2 vs Group B #1 | G170: =Qualifiers!$D$14 -> A3 | H170: =Qualifiers!$E$14 -> B4 | I170: =Qualifiers!$E$14 -> B4 | J170: =IF(I170="","PENDING",IF(OR(I170=G170,I170=H170),"VALID","CHECK WINNER")) -> VALID | M170: =IF(J170="VALID",IF(I170=G170,H170,G170),"") -> A3 | N170: =IF(J170="VALID","YES","NO") -> YES | O170: Source: SEMIS AND FINAL.pdf
A171: 166 | B171: 6:00 PM-6:30 PM | C171: Pickleball | D171: Girls Doubles | E171: SF2 | F171: Group A #2 vs Group B #1 | G171: =Qualifiers!$D$15 -> A3 | H171: =Qualifiers!$E$15 -> B4 | I171: =Qualifiers!$E$15 -> B4 | J171: =IF(I171="","PENDING",IF(OR(I171=G171,I171=H171),"VALID","CHECK WINNER")) -> VALID | M171: =IF(J171="VALID",IF(I171=G171,H171,G171),"") -> A3 | N171: =IF(J171="VALID","YES","NO") -> YES | O171: Source: SEMIS AND FINAL.pdf
A172: 167 | B172: 6:00 PM-6:30 PM | C172: Pickleball | D172: Mixed Doubles | E172: SF2 | F172: Group A #2 vs Group B #1 | G172: =Qualifiers!$D$16 -> A3 | H172: =Qualifiers!$E$16 -> B4 | I172: =Qualifiers!$E$16 -> B4 | J172: =IF(I172="","PENDING",IF(OR(I172=G172,I172=H172),"VALID","CHECK WINNER")) -> VALID | M172: =IF(J172="VALID",IF(I172=G172,H172,G172),"") -> A3 | N172: =IF(J172="VALID","YES","NO") -> YES | O172: Source: SEMIS AND FINAL.pdf
...

Sheet Player Usage
A1: PLAYER APPEARANCE & ELIGIBILITY TRACKER | B1: PLAYER APPEARANCE & ELIGIBILITY TRACKER | C1: PLAYER APPEARANCE & ELIGIBILITY TRACKER | D1: PLAYER APPEARANCE & ELIGIBILITY TRACKER | E1: PLAYER APPEARANCE & ELIGIBILITY TRACKER | F1: PLAYER APPEARANCE & ELIGIBILITY TRACKER | G1: PLAYER APPEARANCE & ELIGIBILITY TRACKER | H1: PLAYER APPEARANCE & ELIGIBILITY TRACKER | I1: PLAYER APPEARANCE & ELIGIBILITY TRACKER | J1: PLAYER APPEARANCE & ELIGIBILITY TRACKER | K1: PLAYER APPEARANCE & ELIGIBILITY TRACKER | L1: PLAYER APPEARANCE & ELIGIBILITY TRACKER | M1: PLAYER APPEARANCE & ELIGIBILITY TRACKER | N1: PLAYER APPEARANCE & ELIGIBILITY TRACKER | O1: PLAYER APPEARANCE & ELIGIBILITY TRACKER
A2: PLAYER APPEARANCE & ELIGIBILITY TRACKER | B2: PLAYER APPEARANCE & ELIGIBILITY TRACKER | C2: PLAYER APPEARANCE & ELIGIBILITY TRACKER | D2: PLAYER APPEARANCE & ELIGIBILITY TRACKER | E2: PLAYER APPEARANCE & ELIGIBILITY TRACKER | F2: PLAYER APPEARANCE & ELIGIBILITY TRACKER | G2: PLAYER APPEARANCE & ELIGIBILITY TRACKER | H2: PLAYER APPEARANCE & ELIGIBILITY TRACKER | I2: PLAYER APPEARANCE & ELIGIBILITY TRACKER | J2: PLAYER APPEARANCE & ELIGIBILITY TRACKER | K2: PLAYER APPEARANCE & ELIGIBILITY TRACKER | L2: PLAYER APPEARANCE & ELIGIBILITY TRACKER | M2: PLAYER APPEARANCE & ELIGIBILITY TRACKER | N2: PLAYER APPEARANCE & ELIGIBILITY TRACKER | O2: PLAYER APPEARANCE & ELIGIBILITY TRACKER
A3: For every doubles match, enter 4 Player Codes in the yellow cells: Players 1-2 for the first team and Players 3-4 for the opposing team. League count is cumulative in match-number order.
A5: Match No. | B5: Time | C5: Stage | D5: Sport | E5: Category | F5: Playing Team | G5: Opponent Team | H5: Side | I5: Player No. in Match | J5: Player Code (INPUT) | K5: Player Name | L5: Roster Check | M5: League Count vs Opponent | N5: Rule Status | O5: Audit Note
A6: 1 | B6: 9:00 AM-9:30 AM | C6: League | D6: Badminton | E6: Boys Doubles | F6: =IF(H6=1,INDEX('Match Results'!$G$6:$G$185,MATCH(A6,'Match Results'!$A$6:$A$185,0)),INDEX('Match Results'!$H$6:$H$185,MATCH(A6,'Match Results'!$A$6:$A$185,0))) -> A1 | G6: =IF(H6=1,INDEX('Match Results'!$H$6:$H$185,MATCH(A6,'Match Results'!$A$6:$A$185,0)),INDEX('Match Results'!$G$6:$G$185,MATCH(A6,'Match Results'!$A$6:$A$185,0))) -> A2 | H6: 1 | I6: 1 | K6: =IF(J6="","",IFERROR(INDEX('Team Rosters'!$C$6:$C$205,MATCH(J6,'Team Rosters'!$B$6:$B$205,0)),"CODE NOT FOUND")) | L6: =IF(J6="","",IF(AND(K6<>"",K6<>"CODE NOT FOUND",LEFT(J6,2)=F6),"VALID","CHECK ROSTER")) | M6: =IF(OR(J6="",C6<>"League",L6<>"VALID"),"",COUNTIFS($J$6:J6,J6,$G$6:G6,G6,$C$6:C6,"League")) | N6: =IF(J6="","",IF(L6<>"VALID","CHECK ROSTER",IF(C6<>"League","NOT APPLICABLE",IF(M6<=2,"OK","VIOLATION")))) | O6: =IF(N6="VIOLATION",K6&" has played "&M6&" league matches against "&G6&"; limit is 2.","")
A7: 1 | B7: 9:00 AM-9:30 AM | C7: League | D7: Badminton | E7: Boys Doubles | F7: =IF(H7=1,INDEX('Match Results'!$G$6:$G$185,MATCH(A7,'Match Results'!$A$6:$A$185,0)),INDEX('Match Results'!$H$6:$H$185,MATCH(A7,'Match Results'!$A$6:$A$185,0))) -> A1 | G7: =IF(H7=1,INDEX('Match Results'!$H$6:$H$185,MATCH(A7,'Match Results'!$A$6:$A$185,0)),INDEX('Match Results'!$G$6:$G$185,MATCH(A7,'Match Results'!$A$6:$A$185,0))) -> A2 | H7: 1 | I7: 2 | K7: =IF(J7="","",IFERROR(INDEX('Team Rosters'!$C$6:$C$205,MATCH(J7,'Team Rosters'!$B$6:$B$205,0)),"CODE NOT FOUND")) | L7: =IF(J7="","",IF(AND(K7<>"",K7<>"CODE NOT FOUND",LEFT(J7,2)=F7),"VALID","CHECK ROSTER")) | M7: =IF(OR(J7="",C7<>"League",L7<>"VALID"),"",COUNTIFS($J$6:J7,J7,$G$6:G7,G7,$C$6:C7,"League")) | N7: =IF(J7="","",IF(L7<>"VALID","CHECK ROSTER",IF(C7<>"League","NOT APPLICABLE",IF(M7<=2,"OK","VIOLATION")))) | O7: =IF(N7="VIOLATION",K7&" has played "&M7&" league matches against "&G7&"; limit is 2.","")
A8: 1 | B8: 9:00 AM-9:30 AM | C8: League | D8: Badminton | E8: Boys Doubles | F8: =IF(H8=1,INDEX('Match Results'!$G$6:$G$185,MATCH(A8,'Match Results'!$A$6:$A$185,0)),INDEX('Match Results'!$H$6:$H$185,MATCH(A8,'Match Results'!$A$6:$A$185,0))) -> A2 | G8: =IF(H8=1,INDEX('Match Results'!$H$6:$H$185,MATCH(A8,'Match Results'!$A$6:$A$185,0)),INDEX('Match Results'!$G$6:$G$185,MATCH(A8,'Match Results'!$A$6:$A$185,0))) -> A1 | H8: 2 | I8: 3 | K8: =IF(J8="","",IFERROR(INDEX('Team Rosters'!$C$6:$C$205,MATCH(J8,'Team Rosters'!$B$6:$B$205,0)),"CODE NOT FOUND")) | L8: =IF(J8="","",IF(AND(K8<>"",K8<>"CODE NOT FOUND",LEFT(J8,2)=F8),"VALID","CHECK ROSTER")) | M8: =IF(OR(J8="",C8<>"League",L8<>"VALID"),"",COUNTIFS($J$6:J8,J8,$G$6:G8,G8,$C$6:C8,"League")) | N8: =IF(J8="","",IF(L8<>"VALID","CHECK ROSTER",IF(C8<>"League","NOT APPLICABLE",IF(M8<=2,"OK","VIOLATION")))) | O8: =IF(N8="VIOLATION",K8&" has played "&M8&" league matches against "&G8&"; limit is 2.","")
A9: 1 | B9: 9:00 AM-9:30 AM | C9: League | D9: Badminton | E9: Boys Doubles | F9: =IF(H9=1,INDEX('Match Results'!$G$6:$G$185,MATCH(A9,'Match Results'!$A$6:$A$185,0)),INDEX('Match Results'!$H$6:$H$185,MATCH(A9,'Match Results'!$A$6:$A$185,0))) -> A2 | G9: =IF(H9=1,INDEX('Match Results'!$H$6:$H$185,MATCH(A9,'Match Results'!$A$6:$A$185,0)),INDEX('Match Results'!$G$6:$G$185,MATCH(A9,'Match Results'!$A$6:$A$185,0))) -> A1 | H9: 2 | I9: 4 | K9: =IF(J9="","",IFERROR(INDEX('Team Rosters'!$C$6:$C$205,MATCH(J9,'Team Rosters'!$B$6:$B$205,0)),"CODE NOT FOUND")) | L9: =IF(J9="","",IF(AND(K9<>"",K9<>"CODE NOT FOUND",LEFT(J9,2)=F9),"VALID","CHECK ROSTER")) | M9: =IF(OR(J9="",C9<>"League",L9<>"VALID"),"",COUNTIFS($J$6:J9,J9,$G$6:G9,G9,$C$6:C9,"League")) | N9: =IF(J9="","",IF(L9<>"VALID","CHECK ROSTER",IF(C9<>"League","NOT APPLICABLE",IF(M9<=2,"OK","VIOLATION")))) | O9: =IF(N9="VIOLATION",K9&" has played "&M9&" league matches against "&G9&"; limit is 2.","")
A10: 2 | B10: 9:00 AM-9:30 AM | C10: League | D10: Badminton | E10: Girls Doubles | F10: =IF(H10=1,INDEX('Match Results'!$G$6:$G$185,MATCH(A10,'Match Results'!$A$6:$A$185,0)),INDEX('Match Results'!$H$6:$H$185,MATCH(A10,'Match Results'!$A$6:$A$185,0))) -> A3 | G10: =IF(H10=1,INDEX('Match Results'!$H$6:$H$185,MATCH(A10,'Match Results'!$A$6:$A$185,0)),INDEX('Match Results'!$G$6:$G$185,MATCH(A10,'Match Results'!$A$6:$A$185,0))) -> A4 | H10: 1 | I10: 1 | K10: =IF(J10="","",IFERROR(INDEX('Team Rosters'!$C$6:$C$205,MATCH(J10,'Team Rosters'!$B$6:$B$205,0)),"CODE NOT FOUND")) | L10: =IF(J10="","",IF(AND(K10<>"",K10<>"CODE NOT FOUND",LEFT(J10,2)=F10),"VALID","CHECK ROSTER")) | M10: =IF(OR(J10="",C10<>"League",L10<>"VALID"),"",COUNTIFS($J$6:J10,J10,$G$6:G10,G10,$C$6:C10,"League")) | N10: =IF(J10="","",IF(L10<>"VALID","CHECK ROSTER",IF(C10<>"League","NOT APPLICABLE",IF(M10<=2,"OK","VIOLATION"))))
A11: 2 | B11: 9:00 AM-9:30 AM | C11: League | D11: Badminton | E11: Girls Doubles | F11: =IF(H11=1,INDEX('Match Results'!$G$6:$G$185,MATCH(A11,'Match Results'!$A$6:$A$185,0)),INDEX('Match Results'!$H$6:$H$185,MATCH(A11,'Match Results'!$A$6:$A$185,0))) -> A3 | G11: =IF(H11=1,INDEX('Match Results'!$H$6:$H$185,MATCH(A11,'Match Results'!$A$6:$A$185,0)),INDEX('Match Results'!$G$6:$G$185,MATCH(A11,'Match Results'!$A$6:$A$185,0))) -> A4 | H11: 1 | I11: 2 | K11: =IF(J11="","",IFERROR(INDEX('Team Rosters'!$C$6:$C$205,MATCH(J11,'Team Rosters'!$B$6:$B$205,0)),"CODE NOT FOUND")) | L11: =IF(J11="","",IF(AND(K11<>"",K11<>"CODE NOT FOUND",LEFT(J11,2)=F11),"VALID","CHECK ROSTER")) | M11: =IF(OR(J11="",C11<>"League",L11<>"VALID"),"",COUNTIFS($J$6:J11,J11,$G$6:G11,G11,$C$6:C11,"League")) | N11: =IF(J11="","",IF(L11<>"VALID","CHECK ROSTER",IF(C11<>"League","NOT APPLICABLE",IF(M11<=2,"OK","VIOLATION")))) | O11: =IF(N11="VIOLATION",K11&" has played "&M11&" league matches against "&G11&"; limit is 2.","")
A12: 2 | B12: 9:00 AM-9:30 AM | C12: League | D12: Badminton | E12: Girls Doubles | F12: =IF(H12=1,INDEX('Match Results'!$G$6:$G$185,MATCH(A12,'Match Results'!$A$6:$A$185,0)),INDEX('Match Results'!$H$6:$H$185,MATCH(A12,'Match Results'!$A$6:$A$185,0))) -> A4 | G12: =IF(H12=1,INDEX('Match Results'!$H$6:$H$185,MATCH(A12,'Match Results'!$A$6:$A$185,0)),INDEX('Match Results'!$G$6:$G$185,MATCH(A12,'Match Results'!$A$6:$A$185,0))) -> A3 | H12: 2 | I12: 3 | K12: =IF(J12="","",IFERROR(INDEX('Team Rosters'!$C$6:$C$205,MATCH(J12,'Team Rosters'!$B$6:$B$205,0)),"CODE NOT FOUND")) | L12: =IF(J12="","",IF(AND(K12<>"",K12<>"CODE NOT FOUND",LEFT(J12,2)=F12),"VALID","CHECK ROSTER")) | M12: =IF(OR(J12="",C12<>"League",L12<>"VALID"),"",COUNTIFS($J$6:J12,J12,$G$6:G12,G12,$C$6:C12,"League")) | N12: =IF(J12="","",IF(L12<>"VALID","CHECK ROSTER",IF(C12<>"League","NOT APPLICABLE",IF(M12<=2,"OK","VIOLATION")))) | O12: =IF(N12="VIOLATION",K12&" has played "&M12&" league matches against "&G12&"; limit is 2.","")
A13: 2 | B13: 9:00 AM-9:30 AM | C13: League | D13: Badminton | E13: Girls Doubles | F13: =IF(H13=1,INDEX('Match Results'!$G$6:$G$185,MATCH(A13,'Match Results'!$A$6:$A$185,0)),INDEX('Match Results'!$H$6:$H$185,MATCH(A13,'Match Results'!$A$6:$A$185,0))) -> A4 | G13: =IF(H13=1,INDEX('Match Results'!$H$6:$H$185,MATCH(A13,'Match Results'!$A$6:$A$185,0)),INDEX('Match Results'!$G$6:$G$185,MATCH(A13,'Match Results'!$A$6:$A$185,0))) -> A3 | H13: 2 | I13: 4 | K13: =IF(J13="","",IFERROR(INDEX('Team Rosters'!$C$6:$C$205,MATCH(J13,'Team Rosters'!$B$6:$B$205,0)),"CODE NOT FOUND")) | L13: =IF(J13="","",IF(AND(K13<>"",K13<>"CODE NOT FOUND",LEFT(J13,2)=F13),"VALID","CHECK ROSTER")) | M13: =IF(OR(J13="",C13<>"League",L13<>"VALID"),"",COUNTIFS($J$6:J13,J13,$G$6:G13,G13,$C$6:C13,"League")) | N13: =IF(J13="","",IF(L13<>"VALID","CHECK ROSTER",IF(C13<>"League","NOT APPLICABLE",IF(M13<=2,"OK","VIOLATION")))) | O13: =IF(N13="VIOLATION",K13&" has played "&M13&" league matches against "&G13&"; limit is 2.","")
A14: 3 | B14: 9:00 AM-9:30 AM | C14: League | D14: Badminton | E14: Mixed Doubles | F14: =IF(H14=1,INDEX('Match Results'!$G$6:$G$185,MATCH(A14,'Match Results'!$A$6:$A$185,0)),INDEX('Match Results'!$H$6:$H$185,MATCH(A14,'Match Results'!$A$6:$A$185,0))) -> B1 | G14: =IF(H14=1,INDEX('Match Results'!$H$6:$H$185,MATCH(A14,'Match Results'!$A$6:$A$185,0)),INDEX('Match Results'!$G$6:$G$185,MATCH(A14,'Match Results'!$A$6:$A$185,0))) -> B4 | H14: 1 | I14: 1 | K14: =IF(J14="","",IFERROR(INDEX('Team Rosters'!$C$6:$C$205,MATCH(J14,'Team Rosters'!$B$6:$B$205,0)),"CODE NOT FOUND")) | L14: =IF(J14="","",IF(AND(K14<>"",K14<>"CODE NOT FOUND",LEFT(J14,2)=F14),"VALID","CHECK ROSTER")) | M14: =IF(OR(J14="",C14<>"League",L14<>"VALID"),"",COUNTIFS($J$6:J14,J14,$G$6:G14,G14,$C$6:C14,"League")) | N14: =IF(J14="","",IF(L14<>"VALID","CHECK ROSTER",IF(C14<>"League","NOT APPLICABLE",IF(M14<=2,"OK","VIOLATION")))) | O14: =IF(N14="VIOLATION",K14&" has played "&M14&" league matches against "&G14&"; limit is 2.","")
A15: 3 | B15: 9:00 AM-9:30 AM | C15: League | D15: Badminton | E15: Mixed Doubles | F15: =IF(H15=1,INDEX('Match Results'!$G$6:$G$185,MATCH(A15,'Match Results'!$A$6:$A$185,0)),INDEX('Match Results'!$H$6:$H$185,MATCH(A15,'Match Results'!$A$6:$A$185,0))) -> B1 | G15: =IF(H15=1,INDEX('Match Results'!$H$6:$H$185,MATCH(A15,'Match Results'!$A$6:$A$185,0)),INDEX('Match Results'!$G$6:$G$185,MATCH(A15,'Match Results'!$A$6:$A$185,0))) -> B4 | H15: 1 | I15: 2 | K15: =IF(J15="","",IFERROR(INDEX('Team Rosters'!$C$6:$C$205,MATCH(J15,'Team Rosters'!$B$6:$B$205,0)),"CODE NOT FOUND")) | L15: =IF(J15="","",IF(AND(K15<>"",K15<>"CODE NOT FOUND",LEFT(J15,2)=F15),"VALID","CHECK ROSTER")) | M15: =IF(OR(J15="",C15<>"League",L15<>"VALID"),"",COUNTIFS($J$6:J15,J15,$G$6:G15,G15,$C$6:C15,"League")) | N15: =IF(J15="","",IF(L15<>"VALID","CHECK ROSTER",IF(C15<>"League","NOT APPLICABLE",IF(M15<=2,"OK","VIOLATION")))) | O15: =IF(N15="VIOLATION",K15&" has played "&M15&" league matches against "&G15&"; limit is 2.","")
A16: 3 | B16: 9:00 AM-9:30 AM | C16: League | D16: Badminton | E16: Mixed Doubles | F16: =IF(H16=1,INDEX('Match Results'!$G$6:$G$185,MATCH(A16,'Match Results'!$A$6:$A$185,0)),INDEX('Match Results'!$H$6:$H$185,MATCH(A16,'Match Results'!$A$6:$A$185,0))) -> B4 | G16: =IF(H16=1,INDEX('Match Results'!$H$6:$H$185,MATCH(A16,'Match Results'!$A$6:$A$185,0)),INDEX('Match Results'!$G$6:$G$185,MATCH(A16,'Match Results'!$A$6:$A$185,0))) -> B1 | H16: 2 | I16: 3 | K16: =IF(J16="","",IFERROR(INDEX('Team Rosters'!$C$6:$C$205,MATCH(J16,'Team Rosters'!$B$6:$B$205,0)),"CODE NOT FOUND")) | L16: =IF(J16="","",IF(AND(K16<>"",K16<>"CODE NOT FOUND",LEFT(J16,2)=F16),"VALID","CHECK ROSTER")) | M16: =IF(OR(J16="",C16<>"League",L16<>"VALID"),"",COUNTIFS($J$6:J16,J16,$G$6:G16,G16,$C$6:C16,"League")) | N16: =IF(J16="","",IF(L16<>"VALID","CHECK ROSTER",IF(C16<>"League","NOT APPLICABLE",IF(M16<=2,"OK","VIOLATION")))) | O16: =IF(N16="VIOLATION",K16&" has played "&M16&" league matches against "&G16&"; limit is 2.","")
A17: 3 | B17: 9:00 AM-9:30 AM | C17: League | D17: Badminton | E17: Mixed Doubles | F17: =IF(H17=1,INDEX('Match Results'!$G$6:$G$185,MATCH(A17,'Match Results'!$A$6:$A$185,0)),INDEX('Match Results'!$H$6:$H$185,MATCH(A17,'Match Results'!$A$6:$A$185,0))) -> B4 | G17: =IF(H17=1,INDEX('Match Results'!$H$6:$H$185,MATCH(A17,'Match Results'!$A$6:$A$185,0)),INDEX('Match Results'!$G$6:$G$185,MATCH(A17,'Match Results'!$A$6:$A$185,0))) -> B1 | H17: 2 | I17: 4 | K17: =IF(J17="","",IFERROR(INDEX('Team Rosters'!$C$6:$C$205,MATCH(J17,'Team Rosters'!$B$6:$B$205,0)),"CODE NOT FOUND")) | L17: =IF(J17="","",IF(AND(K17<>"",K17<>"CODE NOT FOUND",LEFT(J17,2)=F17),"VALID","CHECK ROSTER")) | M17: =IF(OR(J17="",C17<>"League",L17<>"VALID"),"",COUNTIFS($J$6:J17,J17,$G$6:G17,G17,$C$6:C17,"League")) | N17: =IF(J17="","",IF(L17<>"VALID","CHECK ROSTER",IF(C17<>"League","NOT APPLICABLE",IF(M17<=2,"OK","VIOLATION")))) | O17: =IF(N17="VIOLATION",K17&" has played "&M17&" league matches against "&G17&"; limit is 2.","")
A18: 4 | B18: 9:00 AM-9:30 AM | C18: League | D18: Pickleball | E18: Girls Doubles | F18: =IF(H18=1,INDEX('Match Results'!$G$6:$G$185,MATCH(A18,'Match Results'!$A$6:$A$185,0)),INDEX('Match Results'!$H$6:$H$185,MATCH(A18,'Match Results'!$A$6:$A$185,0))) -> A1 | G18: =IF(H18=1,INDEX('Match Results'!$H$6:$H$185,MATCH(A18,'Match Results'!$A$6:$A$185,0)),INDEX('Match Results'!$G$6:$G$185,MATCH(A18,'Match Results'!$A$6:$A$185,0))) -> A4 | H18: 1 | I18: 1 | K18: =IF(J18="","",IFERROR(INDEX('Team Rosters'!$C$6:$C$205,MATCH(J18,'Team Rosters'!$B$6:$B$205,0)),"CODE NOT FOUND")) | L18: =IF(J18="","",IF(AND(K18<>"",K18<>"CODE NOT FOUND",LEFT(J18,2)=F18),"VALID","CHECK ROSTER")) | M18: =IF(OR(J18="",C18<>"League",L18<>"VALID"),"",COUNTIFS($J$6:J18,J18,$G$6:G18,G18,$C$6:C18,"League")) | N18: =IF(J18="","",IF(L18<>"VALID","CHECK ROSTER",IF(C18<>"League","NOT APPLICABLE",IF(M18<=2,"OK","VIOLATION")))) | O18: =IF(N18="VIOLATION",K18&" has played "&M18&" league matches against "&G18&"; limit is 2.","")
A19: 4 | B19: 9:00 AM-9:30 AM | C19: League | D19: Pickleball | E19: Girls Doubles | F19: =IF(H19=1,INDEX('Match Results'!$G$6:$G$185,MATCH(A19,'Match Results'!$A$6:$A$185,0)),INDEX('Match Results'!$H$6:$H$185,MATCH(A19,'Match Results'!$A$6:$A$185,0))) -> A1 | G19: =IF(H19=1,INDEX('Match Results'!$H$6:$H$185,MATCH(A19,'Match Results'!$A$6:$A$185,0)),INDEX('Match Results'!$G$6:$G$185,MATCH(A19,'Match Results'!$A$6:$A$185,0))) -> A4 | H19: 1 | I19: 2 | K19: =IF(J19="","",IFERROR(INDEX('Team Rosters'!$C$6:$C$205,MATCH(J19,'Team Rosters'!$B$6:$B$205,0)),"CODE NOT FOUND")) | L19: =IF(J19="","",IF(AND(K19<>"",K19<>"CODE NOT FOUND",LEFT(J19,2)=F19),"VALID","CHECK ROSTER")) | M19: =IF(OR(J19="",C19<>"League",L19<>"VALID"),"",COUNTIFS($J$6:J19,J19,$G$6:G19,G19,$C$6:C19,"League")) | N19: =IF(J19="","",IF(L19<>"VALID","CHECK ROSTER",IF(C19<>"League","NOT APPLICABLE",IF(M19<=2,"OK","VIOLATION")))) | O19: =IF(N19="VIOLATION",K19&" has played "&M19&" league matches against "&G19&"; limit is 2.","")
A20: 4 | B20: 9:00 AM-9:30 AM | C20: League | D20: Pickleball | E20: Girls Doubles | F20: =IF(H20=1,INDEX('Match Results'!$G$6:$G$185,MATCH(A20,'Match Results'!$A$6:$A$185,0)),INDEX('Match Results'!$H$6:$H$185,MATCH(A20,'Match Results'!$A$6:$A$185,0))) -> A4 | G20: =IF(H20=1,INDEX('Match Results'!$H$6:$H$185,MATCH(A20,'Match Results'!$A$6:$A$185,0)),INDEX('Match Results'!$G$6:$G$185,MATCH(A20,'Match Results'!$A$6:$A$185,0))) -> A1 | H20: 2 | I20: 3 | K20: =IF(J20="","",IFERROR(INDEX('Team Rosters'!$C$6:$C$205,MATCH(J20,'Team Rosters'!$B$6:$B$205,0)),"CODE NOT FOUND")) | L20: =IF(J20="","",IF(AND(K20<>"",K20<>"CODE NOT FOUND",LEFT(J20,2)=F20),"VALID","CHECK ROSTER")) | M20: =IF(OR(J20="",C20<>"League",L20<>"VALID"),"",COUNTIFS($J$6:J20,J20,$G$6:G20,G20,$C$6:C20,"League")) | N20: =IF(J20="","",IF(L20<>"VALID","CHECK ROSTER",IF(C20<>"League","NOT APPLICABLE",IF(M20<=2,"OK","VIOLATION")))) | O20: =IF(N20="VIOLATION",K20&" has played "&M20&" league matches against "&G20&"; limit is 2.","")
A21: 4 | B21: 9:00 AM-9:30 AM | C21: League | D21: Pickleball | E21: Girls Doubles | F21: =IF(H21=1,INDEX('Match Results'!$G$6:$G$185,MATCH(A21,'Match Results'!$A$6:$A$185,0)),INDEX('Match Results'!$H$6:$H$185,MATCH(A21,'Match Results'!$A$6:$A$185,0))) -> A4 | G21: =IF(H21=1,INDEX('Match Results'!$H$6:$H$185,MATCH(A21,'Match Results'!$A$6:$A$185,0)),INDEX('Match Results'!$G$6:$G$185,MATCH(A21,'Match Results'!$A$6:$A$185,0))) -> A1 | H21: 2 | I21: 4 | K21: =IF(J21="","",IFERROR(INDEX('Team Rosters'!$C$6:$C$205,MATCH(J21,'Team Rosters'!$B$6:$B$205,0)),"CODE NOT FOUND")) | L21: =IF(J21="","",IF(AND(K21<>"",K21<>"CODE NOT FOUND",LEFT(J21,2)=F21),"VALID","CHECK ROSTER")) | M21: =IF(OR(J21="",C21<>"League",L21<>"VALID"),"",COUNTIFS($J$6:J21,J21,$G$6:G21,G21,$C$6:C21,"League")) | N21: =IF(J21="","",IF(L21<>"VALID","CHECK ROSTER",IF(C21<>"League","NOT APPLICABLE",IF(M21<=2,"OK","VIOLATION")))) | O21: =IF(N21="VIOLATION",K21&" has played "&M21&" league matches against "&G21&"; limit is 2.","")
A22: 5 | B22: 9:00 AM-9:30 AM | C22: League | D22: Pickleball | E22: Mixed Doubles | F22: =IF(H22=1,INDEX('Match Results'!$G$6:$G$185,MATCH(A22,'Match Results'!$A$6:$A$185,0)),INDEX('Match Results'!$H$6:$H$185,MATCH(A22,'Match Results'!$A$6:$A$185,0))) -> A2 | G22: =IF(H22=1,INDEX('Match Results'!$H$6:$H$185,MATCH(A22,'Match Results'!$A$6:$A$185,0)),INDEX('Match Results'!$G$6:$G$185,MATCH(A22,'Match Results'!$A$6:$A$185,0))) -> A3 | H22: 1 | I22: 1 | K22: =IF(J22="","",IFERROR(INDEX('Team Rosters'!$C$6:$C$205,MATCH(J22,'Team Rosters'!$B$6:$B$205,0)),"CODE NOT FOUND")) | L22: =IF(J22="","",IF(AND(K22<>"",K22<>"CODE NOT FOUND",LEFT(J22,2)=F22),"VALID","CHECK ROSTER")) | M22: =IF(OR(J22="",C22<>"League",L22<>"VALID"),"",COUNTIFS($J$6:J22,J22,$G$6:G22,G22,$C$6:C22,"League")) | N22: =IF(J22="","",IF(L22<>"VALID","CHECK ROSTER",IF(C22<>"League","NOT APPLICABLE",IF(M22<=2,"OK","VIOLATION")))) | O22: =IF(N22="VIOLATION",K22&" has played "&M22&" league matches against "&G22&"; limit is 2.","")
... A875: 181 | B875: 8:30 PM-9:00 PM | C875: Final | D875: Football | E875: Boys | F875: =IF(H875=1,INDEX('Match Results'!$G$6:$G$185,MATCH(A875,'Match Results'!$A$6:$A$185,0)),INDEX('Match Results'!$H$6:$H$185,MATCH(A875,'Match Results'!$A$6:$A$185,0))) -> B4 | G875: =IF(H875=1,INDEX('Match Results'!$H$6:$H$185,MATCH(A875,'Match Results'!$A$6:$A$185,0)),INDEX('Match Results'!$G$6:$G$185,MATCH(A875,'Match Results'!$A$6:$A$185,0))) -> B3 | H875: 2 | I875: 14 | K875: =IF(J875="","",IFERROR(INDEX('Team Rosters'!$C$6:$C$205,MATCH(J875,'Team Rosters'!$B$6:$B$205,0)),"CODE NOT FOUND")) | L875: =IF(J875="","",IF(AND(K875<>"",K875<>"CODE NOT FOUND",LEFT(J875,2)=F875),"VALID","CHECK ROSTER")) | M875: =IF(OR(J875="",C875<>"League",L875<>"VALID"),"",COUNTIFS($J$6:J875,J875,$G$6:G875,G875,$C$6:C875,"League")) | N875: =IF(J875="","",IF(L875<>"VALID","CHECK ROSTER",IF(C875<>"League","NOT APPLICABLE",IF(M875<=2,"OK","VIOLATION")))) | O875: =IF(N875="VIOLATION",K875&" has played "&M875&" league matches against "&G875&"; limit is 2.","")

Sheet Schedule
A1: MASTER MATCH SCHEDULE | B1: MASTER MATCH SCHEDULE | C1: MASTER MATCH SCHEDULE | D1: MASTER MATCH SCHEDULE | E1: MASTER MATCH SCHEDULE | F1: MASTER MATCH SCHEDULE | G1: MASTER MATCH SCHEDULE | H1: MASTER MATCH SCHEDULE | I1: MASTER MATCH SCHEDULE | J1: MASTER MATCH SCHEDULE
A2: MASTER MATCH SCHEDULE | B2: MASTER MATCH SCHEDULE | C2: MASTER MATCH SCHEDULE | D2: MASTER MATCH SCHEDULE | E2: MASTER MATCH SCHEDULE | F2: MASTER MATCH SCHEDULE | G2: MASTER MATCH SCHEDULE | H2: MASTER MATCH SCHEDULE | I2: MASTER MATCH SCHEDULE | J2: MASTER MATCH SCHEDULE
A4: Match No. | B4: Block | C4: Time | D4: Sport | E4: Category | F4: Stage | G4: Group | H4: Fixture | I4: Facility | J4: Source
A5: 1 | B5: 1 | C5: 9:00 AM-9:30 AM | D5: Badminton | E5: Boys Doubles | F5: League | G5: A | H5: A1 vs A2 | I5: C1 | J5: Official PDF
A6: 2 | B6: 1 | C6: 9:00 AM-9:30 AM | D6: Badminton | E6: Girls Doubles | F6: League | G6: A | H6: A3 vs A4 | I6: C2 | J6: Official PDF
A7: 3 | B7: 1 | C7: 9:00 AM-9:30 AM | D7: Badminton | E7: Mixed Doubles | F7: League | G7: B | H7: B1 vs B4 | I7: C3 | J7: Official PDF
A8: 4 | B8: 1 | C8: 9:00 AM-9:30 AM | D8: Pickleball | E8: Girls Doubles | F8: League | G8: A | H8: A1 vs A4 | I8: P1 | J8: Official PDF
A9: 5 | B9: 1 | C9: 9:00 AM-9:30 AM | D9: Pickleball | E9: Mixed Doubles | F9: League | G9: A | H9: A2 vs A3 | I9: P2 | J9: Official PDF
A10: 6 | B10: 1 | C10: 9:00 AM-9:30 AM | D10: Pickleball | E10: Boys Doubles | F10: League | G10: B | H10: B2 vs B3 | I10: P3 | J10: Official PDF
A11: 7 | B11: 1 | C11: 9:00 AM-9:30 AM | D11: Table Tennis | E11: Boys Doubles | F11: League | G11: B | H11: B1 vs B2 | I11: TT1 | J11: Official PDF
A12: 8 | B12: 1 | C12: 9:00 AM-9:30 AM | D12: Table Tennis | E12: Mixed Doubles | F12: League | G12: B | H12: B3 vs B4 | I12: TT2 | J12: Official PDF
A13: 9 | B13: 1 | C13: 9:00 AM-9:30 AM | D13: Carrom | E13: Girls Doubles | F13: League | G13: A | H13: A1 vs A3 | I13: C1 | J13: Official PDF
A14: 10 | B14: 1 | C14: 9:00 AM-9:30 AM | D14: Carrom | E14: Boys Doubles | F14: League | G14: A | H14: A2 vs A4 | I14: C2 | J14: Official PDF
A15: 11 | B15: 1 | C15: 9:00 AM-9:30 AM | D15: Carrom | E15: Mixed Doubles | F15: League | G15: B | H15: B2 vs B4 | I15: C3 | J15: Official PDF
A16: 12 | B16: 1 | C16: 9:00 AM-9:30 AM | D16: Football | E16: Boys | F16: League | G16: B | H16: B1 vs B3 | I16: Football Ground | J16: Official PDF
... A148: 144 | B148: 12 | C148: 2:30 PM-3:00 PM | D148: Football | E148: Boys | F148: League | G148: A | H148: A1 vs A2 | I148: Football Ground | J148: Official PDF
A149: 145 | B149: 13 | C149: 3:30 PM-4:00 PM | D149: Carrom | E149: Boys Doubles | F149: SF1 | H149: Group A #1 vs Group B #2 | J149: SEMIS AND FINAL.pdf
A150: 146 | B150: 13 | C150: 3:30 PM-4:00 PM | D150: Carrom | E150: Girls Doubles | F150: SF1 | H150: Group A #1 vs Group B #2 | J150: SEMIS AND FINAL.pdf
A151: 147 | B151: 13 | C151: 3:30 PM-4:00 PM | D151: Carrom | E151: Mixed Doubles | F151: SF1 | H151: Group A #1 vs Group B #2 | J151: SEMIS AND FINAL.pdf
A152: 148 | B152: 13 | C152: 3:30 PM-4:00 PM | D152: Table Tennis | E152: Boys Doubles | F152: SF1 | H152: Group A #1 vs Group B #2 | J152: SEMIS AND FINAL.pdf
A153: 149 | B153: 13 | C153: 3:30 PM-4:00 PM | D153: Table Tennis | E153: Mixed Doubles | F153: SF1 | H153: Group A #1 vs Group B #2 | J153: SEMIS AND FINAL.pdf
A154: 150 | B154: 14 | C154: 4:00 PM-4:30 PM | D154: Carrom | E154: Boys Doubles | F154: SF2 | H154: Group A #2 vs Group B #1 | J154: SEMIS AND FINAL.pdf
A155: 151 | B155: 14 | C155: 4:00 PM-4:30 PM | D155: Carrom | E155: Girls Doubles | F155: SF2 | H155: Group A #2 vs Group B #1 | J155: SEMIS AND FINAL.pdf
A156: 152 | B156: 14 | C156: 4:00 PM-4:30 PM | D156: Carrom | E156: Mixed Doubles | F156: SF2 | H156: Group A #2 vs Group B #1 | J156: SEMIS AND FINAL.pdf
A157: 153 | B157: 14 | C157: 4:00 PM-4:30 PM | D157: Table Tennis | E157: Boys Doubles | F157: SF2 | H157: Group A #2 vs Group B #1 | J157: SEMIS AND FINAL.pdf
A158: 154 | B158: 14 | C158: 4:00 PM-4:30 PM | D158: Table Tennis | E158: Mixed Doubles | F158: SF2 | H158: Group A #2 vs Group B #1 | J158: SEMIS AND FINAL.pdf
A159: 155 | B159: 15 | C159: 4:30 PM-5:00 PM | D159: Badminton | E159: Boys Doubles | F159: SF1 | H159: Group A #1 vs Group B #2 | J159: SEMIS AND FINAL.pdf
A160: 156 | B160: 15 | C160: 4:30 PM-5:00 PM | D160: Badminton | E160: Girls Doubles | F160: SF1 | H160: Group A #1 vs Group B #2 | J160: SEMIS AND FINAL.pdf
... A184: 181 | B184: 22 | C184: 8:30 PM-9:00 PM | D184: Football | E184: Boys | F184: Final | H184: Winner SF1 vs Winner SF2 | J184: SEMIS AND FINAL.pdf

Sheet Qualifiers
A1: SEMIFINAL QUALIFICATION - GROUP A & GROUP B
A3: Top 2 teams from each group qualify. Points = 10 per valid league win for that sport/category. Equal points use team-code order temporarily; use Manual Seed below if the organizer applies a different tie-break.
A5: Sport | B5: Category | C5: Group A #1 | D5: Group A #2 | E5: Group B #1 | F5: Group B #2 | G5: Tie Check
A6: Carrom | B6: Boys Doubles | C6: =IFERROR(INDEX($D$23:$D$26,MATCH(1,$J$23:$J$26,0)),"") -> A1 | D6: =IFERROR(INDEX($D$23:$D$26,MATCH(2,$J$23:$J$26,0)),"") -> A4 | E6: =IFERROR(INDEX($D$27:$D$30,MATCH(1,$J$27:$J$30,0)),"") -> B4 | F6: =IFERROR(INDEX($D$27:$D$30,MATCH(2,$J$27:$J$30,0)),"") -> B3 | G6: =IF(COUNTIFS($A$23:$A$118,$A6,$B$23:$B$118,$B6,$H$23:$H$118,"TIE - REVIEW")>0,"TIE - REVIEW","OK") -> OK
A7: Carrom | B7: Girls Doubles | C7: =IFERROR(INDEX($D$31:$D$34,MATCH(1,$J$31:$J$34,0)),"") -> A4 | D7: =IFERROR(INDEX($D$31:$D$34,MATCH(2,$J$31:$J$34,0)),"") -> A3 | E7: =IFERROR(INDEX($D$35:$D$38,MATCH(1,$J$35:$J$38,0)),"") -> B4 | F7: =IFERROR(INDEX($D$35:$D$38,MATCH(2,$J$35:$J$38,0)),"") -> B3 | G7: =IF(COUNTIFS($A$23:$A$118,$A7,$B$23:$B$118,$B7,$H$23:$H$118,"TIE - REVIEW")>0,"TIE - REVIEW","OK") -> OK
A8: Carrom | B8: Mixed Doubles | C8: =IFERROR(INDEX($D$39:$D$42,MATCH(1,$J$39:$J$42,0)),"") -> A4 | D8: =IFERROR(INDEX($D$39:$D$42,MATCH(2,$J$39:$J$42,0)),"") -> A3 | E8: =IFERROR(INDEX($D$43:$D$46,MATCH(1,$J$43:$J$46,0)),"") -> B4 | F8: =IFERROR(INDEX($D$43:$D$46,MATCH(2,$J$43:$J$46,0)),"") -> B3 | G8: =IF(COUNTIFS($A$23:$A$118,$A8,$B$23:$B$118,$B8,$H$23:$H$118,"TIE - REVIEW")>0,"TIE - REVIEW","OK") -> OK
A9: Table Tennis | B9: Boys Doubles | C9: =IFERROR(INDEX($D$47:$D$50,MATCH(1,$J$47:$J$50,0)),"") -> A4 | D9: =IFERROR(INDEX($D$47:$D$50,MATCH(2,$J$47:$J$50,0)),"") -> A3 | E9: =IFERROR(INDEX($D$51:$D$54,MATCH(1,$J$51:$J$54,0)),"") -> B4 | F9: =IFERROR(INDEX($D$51:$D$54,MATCH(2,$J$51:$J$54,0)),"") -> B3 | G9: =IF(COUNTIFS($A$23:$A$118,$A9,$B$23:$B$118,$B9,$H$23:$H$118,"TIE - REVIEW")>0,"TIE - REVIEW","OK") -> OK
A10: Table Tennis | B10: Mixed Doubles | C10: =IFERROR(INDEX($D$55:$D$58,MATCH(1,$J$55:$J$58,0)),"") -> A4 | D10: =IFERROR(INDEX($D$55:$D$58,MATCH(2,$J$55:$J$58,0)),"") -> A3 | E10: =IFERROR(INDEX($D$59:$D$62,MATCH(1,$J$59:$J$62,0)),"") -> B4 | F10: =IFERROR(INDEX($D$59:$D$62,MATCH(2,$J$59:$J$62,0)),"") -> B3 | G10: =IF(COUNTIFS($A$23:$A$118,$A10,$B$23:$B$118,$B10,$H$23:$H$118,"TIE - REVIEW")>0,"TIE - REVIEW","OK") -> OK
A11: Badminton | B11: Boys Doubles | C11: =IFERROR(INDEX($D$63:$D$66,MATCH(1,$J$63:$J$66,0)),"") -> A4 | D11: =IFERROR(INDEX($D$63:$D$66,MATCH(2,$J$63:$J$66,0)),"") -> A3 | E11: =IFERROR(INDEX($D$67:$D$70,MATCH(1,$J$67:$J$70,0)),"") -> B4 | F11: =IFERROR(INDEX($D$67:$D$70,MATCH(2,$J$67:$J$70,0)),"") -> B3 | G11: =IF(COUNTIFS($A$23:$A$118,$A11,$B$23:$B$118,$B11,$H$23:$H$118,"TIE - REVIEW")>0,"TIE - REVIEW","OK") -> OK
A12: Badminton | B12: Girls Doubles | C12: =IFERROR(INDEX($D$71:$D$74,MATCH(1,$J$71:$J$74,0)),"") -> A4 | D12: =IFERROR(INDEX($D$71:$D$74,MATCH(2,$J$71:$J$74,0)),"") -> A3 | E12: =IFERROR(INDEX($D$75:$D$78,MATCH(1,$J$75:$J$78,0)),"") -> B4 | F12: =IFERROR(INDEX($D$75:$D$78,MATCH(2,$J$75:$J$78,0)),"") -> B3 | G12: =IF(COUNTIFS($A$23:$A$118,$A12,$B$23:$B$118,$B12,$H$23:$H$118,"TIE - REVIEW")>0,"TIE - REVIEW","OK") -> OK
A13: Badminton | B13: Mixed Doubles | C13: =IFERROR(INDEX($D$79:$D$82,MATCH(1,$J$79:$J$82,0)),"") -> A4 | D13: =IFERROR(INDEX($D$79:$D$82,MATCH(2,$J$79:$J$82,0)),"") -> A3 | E13: =IFERROR(INDEX($D$83:$D$86,MATCH(1,$J$83:$J$86,0)),"") -> B4 | F13: =IFERROR(INDEX($D$83:$D$86,MATCH(2,$J$83:$J$86,0)),"") -> B3 | G13: =IF(COUNTIFS($A$23:$A$118,$A13,$B$23:$B$118,$B13,$H$23:$H$118,"TIE - REVIEW")>0,"TIE - REVIEW","OK") -> OK
A14: Pickleball | B14: Boys Doubles | C14: =IFERROR(INDEX($D$87:$D$90,MATCH(1,$J$87:$J$90,0)),"") -> A4 | D14: =IFERROR(INDEX($D$87:$D$90,MATCH(2,$J$87:$J$90,0)),"") -> A3 | E14: =IFERROR(INDEX($D$91:$D$94,MATCH(1,$J$91:$J$94,0)),"") -> B4 | F14: =IFERROR(INDEX($D$91:$D$94,MATCH(2,$J$91:$J$94,0)),"") -> B3 | G14: =IF(COUNTIFS($A$23:$A$118,$A14,$B$23:$B$118,$B14,$H$23:$H$118,"TIE - REVIEW")>0,"TIE - REVIEW","OK") -> OK
A15: Pickleball | B15: Girls Doubles | C15: =IFERROR(INDEX($D$95:$D$98,MATCH(1,$J$95:$J$98,0)),"") -> A4 | D15: =IFERROR(INDEX($D$95:$D$98,MATCH(2,$J$95:$J$98,0)),"") -> A3 | E15: =IFERROR(INDEX($D$99:$D$102,MATCH(1,$J$99:$J$102,0)),"") -> B4 | F15: =IFERROR(INDEX($D$99:$D$102,MATCH(2,$J$99:$J$102,0)),"") -> B3 | G15: =IF(COUNTIFS($A$23:$A$118,$A15,$B$23:$B$118,$B15,$H$23:$H$118,"TIE - REVIEW")>0,"TIE - REVIEW","OK") -> OK
A16: Pickleball | B16: Mixed Doubles | C16: =IFERROR(INDEX($D$103:$D$106,MATCH(1,$J$103:$J$106,0)),"") -> A4 | D16: =IFERROR(INDEX($D$103:$D$106,MATCH(2,$J$103:$J$106,0)),"") -> A3 | E16: =IFERROR(INDEX($D$107:$D$110,MATCH(1,$J$107:$J$110,0)),"") -> B4 | F16: =IFERROR(INDEX($D$107:$D$110,MATCH(2,$J$107:$J$110,0)),"") -> B3 | G16: =IF(COUNTIFS($A$23:$A$118,$A16,$B$23:$B$118,$B16,$H$23:$H$118,"TIE - REVIEW")>0,"TIE - REVIEW","OK") -> OK
A17: Football | B17: Boys | C17: =IFERROR(INDEX($D$111:$D$114,MATCH(1,$J$111:$J$114,0)),"") -> A4 | D17: =IFERROR(INDEX($D$111:$D$114,MATCH(2,$J$111:$J$114,0)),"") -> A3 | E17: =IFERROR(INDEX($D$115:$D$118,MATCH(1,$J$115:$J$118,0)),"") -> B4 | F17: =IFERROR(INDEX($D$115:$D$118,MATCH(2,$J$115:$J$118,0)),"") -> B3 | G17: =IF(COUNTIFS($A$23:$A$118,$A17,$B$23:$B$118,$B17,$H$23:$H$118,"TIE - REVIEW")>0,"TIE - REVIEW","OK") -> OK
A20: DETAILED GROUP RANKING
A22: Sport | B22: Category | C22: Group | D22: Team | E22: League Wins | F22: Points | G22: Auto Seed | H22: Points Tie | I22: Manual Seed (INPUT) | J22: Final Seed
A23: Carrom | B23: Boys Doubles | C23: A | D23: A1 | E23: =COUNTIFS('Match Results'!$C$6:$C$149,$A23,'Match Results'!$D$6:$D$149,$B23,'Match Results'!$E$6:$E$149,"League",'Match Results'!$I$6:$I$149,$D23,'Match Results'!$J$6:$J$149,"VALID") -> 3 | F23: =E23*10 -> 30 | G23: =1+COUNTIFS($A$23:$A$118,$A23,$B$23:$B$118,$B23,$C$23:$C$118,$C23,$F$23:$F$118,">"&$F23)+COUNTIFS($A$23:$A$118,$A23,$B$23:$B$118,$B23,$C$23:$C$118,$C23,$F$23:$F$118,$F23,$D$23:$D$118,"<"&$D23) -> 1 | H23: =IF(COUNTIFS($A$23:$A$118,$A23,$B$23:$B$118,$B23,$C$23:$C$118,$C23,$F$23:$F$118,$F23)>1,"TIE - REVIEW","") | J23: =IF(I23="",G23,I23) -> 1 | K23: =$A23&"|"&$B23&"|"&$C23&"|"&$J23 -> Carrom|Boys Doubles|A|1
A24: Carrom | B24: Boys Doubles | C24: A | D24: A2 | E24: =COUNTIFS('Match Results'!$C$6:$C$149,$A24,'Match Results'!$D$6:$D$149,$B24,'Match Results'!$E$6:$E$149,"League",'Match Results'!$I$6:$I$149,$D24,'Match Results'!$J$6:$J$149,"VALID") -> 0 | F24: =E24*10 -> 0 | G24: =1+COUNTIFS($A$23:$A$118,$A24,$B$23:$B$118,$B24,$C$23:$C$118,$C24,$F$23:$F$118,">"&$F24)+COUNTIFS($A$23:$A$118,$A24,$B$23:$B$118,$B24,$C$23:$C$118,$C24,$F$23:$F$118,$F24,$D$23:$D$118,"<"&$D24) -> 4 | H24: =IF(COUNTIFS($A$23:$A$118,$A24,$B$23:$B$118,$B24,$C$23:$C$118,$C24,$F$23:$F$118,$F24)>1,"TIE - REVIEW","") | J24: =IF(I24="",G24,I24) -> 4 | K24: =$A24&"|"&$B24&"|"&$C24&"|"&$J24 -> Carrom|Boys Doubles|A|4
A25: Carrom | B25: Boys Doubles | C25: A | D25: A3 | E25: =COUNTIFS('Match Results'!$C$6:$C$149,$A25,'Match Results'!$D$6:$D$149,$B25,'Match Results'!$E$6:$E$149,"League",'Match Results'!$I$6:$I$149,$D25,'Match Results'!$J$6:$J$149,"VALID") -> 1 | F25: =E25*10 -> 10 | G25: =1+COUNTIFS($A$23:$A$118,$A25,$B$23:$B$118,$B25,$C$23:$C$118,$C25,$F$23:$F$118,">"&$F25)+COUNTIFS($A$23:$A$118,$A25,$B$23:$B$118,$B25,$C$23:$C$118,$C25,$F$23:$F$118,$F25,$D$23:$D$118,"<"&$D25) -> 3 | H25: =IF(COUNTIFS($A$23:$A$118,$A25,$B$23:$B$118,$B25,$C$23:$C$118,$C25,$F$23:$F$118,$F25)>1,"TIE - REVIEW","") | J25: =IF(I25="",G25,I25) -> 3 | K25: =$A25&"|"&$B25&"|"&$C25&"|"&$J25 -> Carrom|Boys Doubles|A|3
A26: Carrom | B26: Boys Doubles | C26: A | D26: A4 | E26: =COUNTIFS('Match Results'!$C$6:$C$149,$A26,'Match Results'!$D$6:$D$149,$B26,'Match Results'!$E$6:$E$149,"League",'Match Results'!$I$6:$I$149,$D26,'Match Results'!$J$6:$J$149,"VALID") -> 2 | F26: =E26*10 -> 20 | G26: =1+COUNTIFS($A$23:$A$118,$A26,$B$23:$B$118,$B26,$C$23:$C$118,$C26,$F$23:$F$118,">"&$F26)+COUNTIFS($A$23:$A$118,$A26,$B$23:$B$118,$B26,$C$23:$C$118,$C26,$F$23:$F$118,$F26,$D$23:$D$118,"<"&$D26) -> 2 | H26: =IF(COUNTIFS($A$23:$A$118,$A26,$B$23:$B$118,$B26,$C$23:$C$118,$C26,$F$23:$F$118,$F26)>1,"TIE - REVIEW","") | J26: =IF(I26="",G26,I26) -> 2 | K26: =$A26&"|"&$B26&"|"&$C26&"|"&$J26 -> Carrom|Boys Doubles|A|2
